Exception in Tkinter callback
Traceback (most recent call last):
  File "C:\Users\Admin\AppData\Local\Programs\Python\Python312\Lib\tkinter\__init__.py", line 1968, in __call__
    return self.func(*args)
           ^^^^^^^^^^^^^^^^
  File "D:\Excel Project\main.py", line 202, in insert
    error_insert = Insert.main([var4.get()[0], int(var4.get()[1:])], var1.get(), set_value['path'])
                                ~~~~~~~~~~^^^
IndexError: string index out of range
----------Above 2024-10-05 21:37:23----------

